Testing Nested try block with multiple catch block inside the first catch block of the outer try block PASSED!
Inner TypeError thrown gets caught PASSED!
